<?xml version="1.0" ?>
<!-- =================================================================================== -->
<!-- |    This document was autogenerated by xacro from manipulator_camera.urdf.xacro  | -->
<!-- |    EDITING THIS FILE BY HAND IS NOT RECOMMENDED                                 | -->
<!-- =================================================================================== -->
<robot name="manipulator_camera">
  <link name="world"/>
  <material name="grey">
    <color rgba="0.5 0.5 0.5 1.0"/>
  </material>
  <material name="red">
    <color rgba="0.8 0.0 0.0 1.0"/>
  </material>
  <!-- Link 1 -->
  <link name="link1">
    <visual>
      <origin rpy="0 0 0" xyz="0 0 0"/>
      <geometry>
        <mesh filename="file:///home/steve/Open_Manipulator/OpenManipulatorX_ros2_Humble/install/open_manipulator_x_description/share/open_manipulator_x_description/meshes/chain_link1.stl" scale="0.001 0.001 0.001"/>
      </geometry>
      <material name="grey"/>
    </visual>
    <collision>
      <origin rpy="0 0 0" xyz="0 0 0"/>
      <geometry>
        <mesh filename="file:///home/steve/Open_Manipulator/OpenManipulatorX_ros2_Humble/install/open_manipulator_x_description/share/open_manipulator_x_description/meshes/chain_link1.stl" scale="0.001 0.001 0.001"/>
      </geometry>
    </collision>
    <inertial>
      <origin xyz="3.0876154e-04 0.0000000e+00 -1.2176461e-04"/>
      <mass value="7.9119962e-02"/>
      <inertia ixx="1.2505234e-05" ixy="0.0" ixz="-1.7855208e-07" iyy="2.1898364e-05" iyz="0.0" izz="1.9267361e-05"/>
    </inertial>
  </link>
  <!-- Joint 0 -->
  <joint name="joint0" type="fixed">
    <parent link="world"/>
    <child link="link1"/>
  </joint>
  <!-- Joint 1 -->
  <joint name="joint1" type="revolute">
    <parent link="link1"/>
    <child link="link2"/>
    <origin rpy="0 0 0" xyz="0.012 0.0 0.017"/>
    <axis xyz="0 0 1"/>
    <limit effort="1" lower="-2.82743338823" upper="2.82743338823" velocity="4.8"/>
  </joint>
  <!--  Link 2 -->
  <link name="link2">
    <visual>
      <origin rpy="0 0 0" xyz="0 0 0.019"/>
      <geometry>
        <mesh filename="file:///home/steve/Open_Manipulator/OpenManipulatorX_ros2_Humble/install/open_manipulator_x_description/share/open_manipulator_x_description/meshes/chain_link2.stl" scale="0.001 0.001 0.001"/>
      </geometry>
      <material name="grey"/>
    </visual>
    <collision>
      <origin rpy="0 0 0" xyz="0 0 0.019"/>
      <geometry>
        <mesh filename="file:///home/steve/Open_Manipulator/OpenManipulatorX_ros2_Humble/install/open_manipulator_x_description/share/open_manipulator_x_description/meshes/chain_link2.stl" scale="0.001 0.001 0.001"/>
      </geometry>
    </collision>
    <inertial>
      <origin xyz="-3.0184870e-04 5.4043684e-04 0.047433464e-02"/>
      <mass value="9.8406837e-02"/>
      <inertia ixx="3.4543422e-05" ixy="-1.6031095e-08" ixz="-3.8375155e-07" iyy="3.2689329e-05" iyz="2.8511935e-08" izz="1.8850320e-05"/>
    </inertial>
  </link>
  <!--  Joint 2 -->
  <joint name="joint2" type="revolute">
    <parent link="link2"/>
    <child link="link3"/>
    <origin rpy="0 0 0" xyz="0.0 0.0 0.0595"/>
    <axis xyz="0 1 0"/>
    <limit effort="1" lower="-1.79070781255" upper="1.57079632679" velocity="4.8"/>
  </joint>
  <!--  Link 3 -->
  <link name="link3">
    <visual>
      <origin rpy="0 0 0" xyz="0 0 0"/>
      <geometry>
        <mesh filename="file:///home/steve/Open_Manipulator/OpenManipulatorX_ros2_Humble/install/open_manipulator_x_description/share/open_manipulator_x_description/meshes/chain_link3.stl" scale="0.001 0.001 0.001"/>
      </geometry>
      <material name="grey"/>
    </visual>
    <collision>
      <origin rpy="0 0 0" xyz="0 0 0"/>
      <geometry>
        <mesh filename="file:///home/steve/Open_Manipulator/OpenManipulatorX_ros2_Humble/install/open_manipulator_x_description/share/open_manipulator_x_description/meshes/chain_link3.stl" scale="0.001 0.001 0.001"/>
      </geometry>
    </collision>
    <inertial>
      <origin xyz="1.0308393e-02 3.7743363e-04 1.0170197e-01"/>
      <mass value="1.3850917e-01"/>
      <inertia ixx="3.3055381e-04" ixy="-9.7940978e-08" ixz="-3.8505711e-05" iyy="3.4290447e-04" iyz="-1.5717516e-06" izz="6.0346498e-05"/>
    </inertial>
  </link>
  <!--  Joint 3 -->
  <joint name="joint3" type="revolute">
    <parent link="link3"/>
    <child link="link4"/>
    <origin rpy="0 0 0" xyz="0.024 0 0.128"/>
    <axis xyz="0 1 0"/>
    <limit effort="1" lower="-0.94247779607" upper="1.38230076758" velocity="4.8"/>
  </joint>
  <!--  Link 4 -->
  <link name="link4">
    <visual>
      <origin rpy="0 0 0" xyz="0 0 0"/>
      <geometry>
        <mesh filename="file:///home/steve/Open_Manipulator/OpenManipulatorX_ros2_Humble/install/open_manipulator_x_description/share/open_manipulator_x_description/meshes/chain_link4.stl" scale="0.001 0.001 0.001"/>
      </geometry>
      <material name="grey"/>
    </visual>
    <collision>
      <origin rpy="0 0 0" xyz="0 0 0"/>
      <geometry>
        <mesh filename="file:///home/steve/Open_Manipulator/OpenManipulatorX_ros2_Humble/install/open_manipulator_x_description/share/open_manipulator_x_description/meshes/chain_link4.stl" scale="0.001 0.001 0.001"/>
      </geometry>
    </collision>
    <inertial>
      <origin xyz="9.0909590e-02 3.8929816e-04 2.2413279e-04"/>
      <mass value="1.3274562e-01"/>
      <inertia ixx="3.0654178e-05" ixy="-1.2764155e-06" ixz="-2.6874417e-07" iyy="2.4230292e-04" iyz="1.1559550e-08" izz="2.5155057e-04"/>
    </inertial>
  </link>
  <!--  Joint 4 -->
  <joint name="joint4" type="revolute">
    <parent link="link4"/>
    <child link="link5"/>
    <origin rpy="0 0 0" xyz="0.124 0.0 0.0"/>
    <axis xyz="0 1 0"/>
    <limit effort="1" lower="-1.79070781255" upper="2.04203522483" velocity="4.8"/>
  </joint>
  <!--  Link 5 -->
  <link name="link5">
    <visual>
      <origin rpy="0 0 0" xyz="0 0 0"/>
      <geometry>
        <mesh filename="file:///home/steve/Open_Manipulator/OpenManipulatorX_ros2_Humble/install/open_manipulator_x_description/share/open_manipulator_x_description/meshes/chain_link5.stl" scale="0.001 0.001 0.001"/>
      </geometry>
      <material name="grey"/>
    </visual>
    <collision>
      <origin rpy="0 0 0" xyz="0 0 0"/>
      <geometry>
        <mesh filename="file:///home/steve/Open_Manipulator/OpenManipulatorX_ros2_Humble/install/open_manipulator_x_description/share/open_manipulator_x_description/meshes/chain_link5.stl" scale="0.001 0.001 0.001"/>
      </geometry>
    </collision>
    <inertial>
      <origin xyz="4.4206755e-02 3.6839985e-07 8.9142216e-03"/>
      <mass value="1.4327573e-01"/>
      <inertia ixx="8.0870749e-05" ixy="0.0" ixz="-1.0157896e-06" iyy="7.5980465e-05" iyz="0.0" izz="9.3127351e-05"/>
    </inertial>
  </link>
  <!--  Gripper joint -->
  <joint name="gripper" type="prismatic">
    <parent link="link5"/>
    <child link="gripper_link"/>
    <origin rpy="0 0 0" xyz="0.0817 0.021 0.0"/>
    <axis xyz="0 1 0"/>
    <limit effort="1" lower="-0.010" upper="0.019" velocity="4.8"/>
  </joint>
  <!--  Gripper link -->
  <link name="gripper_link">
    <visual>
      <origin rpy="0 0 0" xyz="0.0 0.0 0"/>
      <geometry>
        <mesh filename="file:///home/steve/Open_Manipulator/OpenManipulatorX_ros2_Humble/install/open_manipulator_x_description/share/open_manipulator_x_description/meshes/chain_link_grip_l.stl" scale="0.001 0.001 0.001"/>
      </geometry>
      <material name="grey"/>
    </visual>
    <collision>
      <origin rpy="0 0 0" xyz="0.0 0.0 0"/>
      <geometry>
        <mesh filename="file:///home/steve/Open_Manipulator/OpenManipulatorX_ros2_Humble/install/open_manipulator_x_description/share/open_manipulator_x_description/meshes/chain_link_grip_l.stl" scale="0.001 0.001 0.001"/>
      </geometry>
    </collision>
    <inertial>
      <origin xyz="0 0 0"/>
      <mass value="1.0e-03"/>
      <inertia ixx="1.0e-03" ixy="0.0" ixz="0.0" iyy="1.0e-03" iyz="0.0" izz="1.0e-03"/>
    </inertial>
  </link>
  <!--  Gripper joint sub -->
  <joint name="gripper_sub" type="prismatic">
    <parent link="link5"/>
    <child link="gripper_link_sub"/>
    <origin rpy="0 0 0" xyz="0.0817 -0.021 0.0"/>
    <axis xyz="0 -1 0"/>
    <limit effort="1" lower="-0.010" upper="0.024" velocity="4.8"/>
    <mimic joint="gripper" multiplier="1"/>
  </joint>
  <!--  Gripper link sub -->
  <link name="gripper_link_sub">
    <visual>
      <origin rpy="0 0 0" xyz="0.0 -0.0 0"/>
      <geometry>
        <mesh filename="file:///home/steve/Open_Manipulator/OpenManipulatorX_ros2_Humble/install/open_manipulator_x_description/share/open_manipulator_x_description/meshes/chain_link_grip_r.stl" scale="0.001 0.001 0.001"/>
      </geometry>
      <material name="grey"/>
    </visual>
    <collision>
      <origin rpy="0 0 0" xyz="0.0 -0.0 0"/>
      <geometry>
        <mesh filename="file:///home/steve/Open_Manipulator/OpenManipulatorX_ros2_Humble/install/open_manipulator_x_description/share/open_manipulator_x_description/meshes/chain_link_grip_r.stl" scale="0.001 0.001 0.001"/>
      </geometry>
    </collision>
    <inertial>
      <origin xyz="0 0 0"/>
      <mass value="1.0e-03"/>
      <inertia ixx="1.0e-03" ixy="0.0" ixz="0.0" iyy="1.0e-03" iyz="0.0" izz="1.0e-03"/>
    </inertial>
  </link>
  <!-- end effector joint -->
  <joint name="end_effector_joint" type="fixed">
    <origin rpy="0 0 0" xyz="0.126 0.0 0.0"/>
    <parent link="link5"/>
    <child link="end_effector_link"/>
  </joint>
  <!-- end effector link -->
  <link name="end_effector_link">
    <visual>
      <origin rpy="0 0 0" xyz="0 0 0"/>
      <geometry>
        <box size="0.01 0.01 0.01"/>
      </geometry>
      <material name="red"/>
    </visual>
    <inertial>
      <origin xyz="0 0 0"/>
      <mass value="1.0e-03"/>
      <inertia ixx="1.0e-03" ixy="0.0" ixz="0.0" iyy="1.0e-03" iyz="0.0" izz="1.0e-03"/>
    </inertial>
  </link>
  <!-- Realsense Camera Joint Position -->
  <joint name="manipulator_camera_joint" type="fixed">
    <axis xyz="0 1 0"/>
    <origin rpy="0 0 0" xyz="0.070 0.032 0.052"/>
    <parent link="link5"/>
    <child link="manipulator_camera_link"/>
  </joint>
  <link name="manipulator_camera_link"/>
  <gazebo>
    <plugin filename="libignition-gazebo-joint-state-publisher-system.so" name="ignition::gazebo::systems::JointStatePublisher"/>
  </gazebo>
  <ros2_control name="mx" type="system">
    <hardware>
      <plugin>ign_ros2_control/IgnitionSystem</plugin>
    </hardware>
    <joint name="joint1">
      <command_interface name="position">
        <param name="min">{-2*pi}</param>
        <param name="max">{2*pi}</param>
      </command_interface>
      <command_interface name="velocity">
        <param name="min">-3.15</param>
        <param name="max">3.15</param>
      </command_interface>
      <state_interface name="position">
        <!-- initial position for the FakeSystem and simulation -->
        <param name="initial_value">0.0</param>
      </state_interface>
      <state_interface name="velocity"/>
      <state_interface name="effort"/>
    </joint>
    <joint name="joint2">
      <command_interface name="position">
        <param name="min">{-2*pi}</param>
        <param name="max">{2*pi}</param>
      </command_interface>
      <command_interface name="velocity">
        <param name="min">-3.15</param>
        <param name="max">3.15</param>
      </command_interface>
      <state_interface name="position">
        <!-- initial position for the FakeSystem and simulation -->
        <param name="initial_value">0.0</param>
      </state_interface>
      <state_interface name="velocity"/>
      <state_interface name="effort"/>
    </joint>
    <joint name="joint3">
      <command_interface name="position">
        <param name="min">{-pi}</param>
        <param name="max">{pi}</param>
      </command_interface>
      <command_interface name="velocity">
        <param name="min">-3.15</param>
        <param name="max">3.15</param>
      </command_interface>
      <state_interface name="position">
        <!-- initial position for the FakeSystem and simulation -->
        <param name="initial_value">0.0</param>
      </state_interface>
      <state_interface name="velocity"/>
      <state_interface name="effort"/>
    </joint>
    <joint name="joint4">
      <command_interface name="position">
        <param name="min">{-2*pi}</param>
        <param name="max">{2*pi}</param>
      </command_interface>
      <command_interface name="velocity">
        <param name="min">-3.2</param>
        <param name="max">3.2</param>
      </command_interface>
      <state_interface name="position">
        <!-- initial position for the FakeSystem and simulation -->
        <param name="initial_value">0.0</param>
      </state_interface>
      <state_interface name="velocity"/>
      <state_interface name="effort"/>
    </joint>
    <joint name="gripper">
      <command_interface name="position">
        <param name="min">{-2*pi}</param>
        <param name="max">{2*pi}</param>
      </command_interface>
      <command_interface name="velocity">
        <param name="min">-3.2</param>
        <param name="max">3.2</param>
      </command_interface>
      <state_interface name="position">
        <!-- initial position for the FakeSystem and simulation -->
        <param name="initial_value">0.0</param>
      </state_interface>
      <state_interface name="velocity"/>
      <state_interface name="effort"/>
    </joint>
    <joint name="gripper_sub">
      <command_interface name="position">
        <param name="min">{-2*pi}</param>
        <param name="max">{2*pi}</param>
      </command_interface>
      <command_interface name="velocity">
        <param name="min">-3.2</param>
        <param name="max">3.2</param>
      </command_interface>
      <state_interface name="position">
        <!-- initial position for the FakeSystem and simulation -->
        <param name="initial_value">0.0</param>
      </state_interface>
      <state_interface name="velocity"/>
      <state_interface name="effort"/>
    </joint>
  </ros2_control>
  <gazebo>
    <plugin filename="libign_ros2_control-system.so" name="ign_ros2_control::IgnitionROS2ControlPlugin">
      <parameters>/home/steve/Open_Manipulator/OpenManipulatorX_ros2_Humble/src/custom/manipulatorx_ign/config/mx_controllers.yaml</parameters>
      <controller_manager_node_name>controller_manager</controller_manager_node_name>
    </plugin>
  </gazebo>
  <!-- realsense camera -->
  <link name="mx/link5/camera_depth"/>
  <joint name="camera_parent_joint" type="fixed">
    <origin rpy="0 0 0" xyz="0 0 0"/>
    <parent link="manipulator_camera_link"/>
    <child link="mx/link5/camera_depth"/>
  </joint>
  <material name="aluminum">
    <color rgba="0.5 0.5 0.5 1"/>
  </material>
  <material name="plastic">
    <color rgba="0.1 0.1 0.1 1"/>
  </material>
  <!-- camera body, with origin at bottom screw mount -->
  <joint name="camera_joint" type="fixed">
    <origin rpy="0 0 0" xyz="-0.005 -0.035 -0.01"/>
    <parent link="mx/link5/camera_depth"/>
    <child link="camera_bottom_screw_frame"/>
  </joint>
  <link name="camera_bottom_screw_frame"/>
  <joint name="camera_link_joint" type="fixed">
    <origin rpy="0 0 0" xyz="0.010600000000000002 0.0175 0.0125"/>
    <parent link="camera_bottom_screw_frame"/>
    <child link="camera_link"/>
  </joint>
  <link name="camera_link">
    <visual>
      <!-- the mesh origin is at front plate in between the two infrared camera axes -->
      <origin rpy="1.5707963267948966 0 1.5707963267948966" xyz="0.0043 -0.0175 0"/>
      <geometry>
        <mesh filename="file:///home/steve/Open_Manipulator/OpenManipulatorX_ros2_Humble/install/realsense2_description/share/realsense2_description/meshes/d435.dae"/>
      </geometry>
    </visual>
    <collision>
      <origin rpy="0 0 0" xyz="0 -0.0175 0"/>
      <geometry>
        <box size="0.02505 0.09 0.025"/>
      </geometry>
    </collision>
    <inertial>
      <!-- The following are not reliable values, and should not be used for modeling -->
      <mass value="0.072"/>
      <origin xyz="0 0 0"/>
      <inertia ixx="0.003881243" ixy="0.0" ixz="0.0" iyy="0.000498940" iyz="0.0" izz="0.003879257"/>
    </inertial>
  </link>
  <gazebo reference="camera_link">
    <sensor name="camera" type="camera">
      <update_rate> 10 </update_rate>
      <topic> image_raw </topic>
      <pose> 0 0 0   0 0 0 </pose>
      <camera name="head">
        <image>
          <width> 1920 </width>
          <height> 1080 </height>
          <format>R8G8B8</format>
        </image>
        <clip>
          <near> 0.02 </near>
          <far> 3 </far>
        </clip>
        <noise>
          <mean> 0.0 </mean>
          <stddev> 0.01 </stddev>
        </noise>
        <lens>
          <type> gnomolical </type>
          <intrinsics>
            <fx>1663</fx>
            <fy>1663</fy>
            <cx>960</cx>
            <cy>540</cy>
            <s>0</s>
          </intrinsics>
          <projection>
            <p_fx>1663</p_fx>
            <p_fy>1663</p_fy>
            <p_cx>960</p_cx>
            <p_cy>540</p_cy>
          </projection>
        </lens>
      </camera>
      <plugin filename="ignition-gazebo-sensors-system" name="ignition::gazebo::systems::Sensors">
          </plugin>
    </sensor>
    <sensor name="camera_depth" type="depth">
      <update_rate> 10 </update_rate>
      <topic> camera_depth </topic>
      <camera>
        <horizontal_fov>1.047198</horizontal_fov>
        <image>
          <width> 480 </width>
          <height> 270 </height>
          <format>R8G8B8</format>
        </image>
        <clip>
          <near>0.02</near>
          <far>3</far>
        </clip>
      </camera>
    </sensor>
  </gazebo>
</robot>
